Workbook

Sheet Сводка
A1: Финмодель
A2: Кейс: до 10 млрд ₽ за 3 года, окупаемость до 3 лет. Период: Q1 2027 – Q4 2029. Деньги — млн ₽.
A3: Синий — ввод; чёрный — формула; зелёный — ссылка на лист; жёлтый — ключевое допущение.
A4: Допущения менять только на листе «Допущения».
A6: 1. Ключевые результаты | B6: Пессимист | C6: База | D6: Оптимист
A7: Окупаемость, квартал проекта (накопленный поток ≥ 0) | B7: =Модель_Пессимист!C117 -> не окупается | C7: =Модель_База!C117 -> не окупается | D7: =Модель_Оптимист!C117 -> 7
A8: Дисконтированная окупаемость, квартал проекта (ставка 15%) | B8: =Модель_Пессимист!C118 -> не окупается | C8: =Модель_База!C118 -> не окупается | D8: =Модель_Оптимист!C118 -> 7
A9: Окупаемость, месяцев | B9: =Модель_Пессимист!C119 -> н/д | C9: =Модель_База!C119 -> н/д | D9: =Модель_Оптимист!C119 -> 21
A10: Пиковая потребность в финансировании, млн ₽ | B10: =Модель_Пессимист!C120 -> 478.11005 | C10: =Модель_База!C120 -> 170.25678 | D10: =Модель_Оптимист!C120 -> 146.93276
A11: Доля от лимита 10 млрд ₽ | B11: =Модель_Пессимист!C121 -> 0.047811005 | C11: =Модель_База!C121 -> 0.017025678 | D11: =Модель_Оптимист!C121 -> 0.014693276
A12: Дополнительная выручка за 3 года, млн ₽ | B12: =Модель_Пессимист!C122 -> 58.03787 | C12: =Модель_База!C122 -> 630.44877 | D12: =Модель_Оптимист!C122 -> 2301.8644
A13: Затраты за 3 года, млн ₽ | B13: =Модель_Пессимист!C123 -> 527.44224 | C13: =Модель_База!C123 -> 642.26951 | D13: =Модель_Оптимист!C123 -> 927.36706
A14: Накопленный чистый поток за 3 года, млн ₽ | B14: =Модель_Пессимист!C124 -> -478.11005 | C14: =Модель_База!C124 -> -106.38806 | D14: =Модель_Оптимист!C124 -> 1029.2177
A15: NPV за 3 года, млн ₽ | B15: =Модель_Пессимист!C125 -> -381.43983 | C15: =Модель_База!C125 -> -106.50067 | D15: =Модель_Оптимист!C125 -> 714.17775
A16: ROI за 3 года | B16: =Модель_Пессимист!C126 -> -0.90646902 | C16: =Модель_База!C126 -> -0.16564395 | D16: =Модель_Оптимист!C126 -> 1.1098277
A17: Run-rate чистого потока на Q12, млн ₽/год | B17: =Модель_Пессимист!C127 -> -164.1546 | C17: =Модель_База!C127 -> 66.667072 | D17: =Модель_Оптимист!C127 -> 844.39361
A18: Отзывов за 3 года, тыс. шт. | B18: =Модель_Пессимист!C128 -> 1476.0051 | C18: =Модель_База!C128 -> 10264.777 | D18: =Модель_Оптимист!C128 -> 18045.687
A19: Чистый прирост сделок за 3 года, тыс. шт. | B19: =Модель_Пессимист!C129 -> 216.97274 | C19: =Модель_База!C129 -> 1992.0082 | D19: =Модель_Оптимист!C129 -> 6600.21
A20: Мин. прирост конверсии: простая окупаемость за 12 кв. | B20: =Модель_Пессимист!C135 -> 0.3881844 | C20: =Модель_База!C135 -> 0.060507692 | D20: =Модель_Оптимист!C135 -> 0.028531037
A21: Мин. прирост конверсии: дисконтированная окупаемость за 12 кв. | B21: =Модель_Пессимист!C134 -> 0.42694901 | C21: =Модель_База!C134 -> 0.064461692 | D21: =Модель_Оптимист!C134 -> 0.031061689
A22: Заложенный прирост конверсии | B22: =Модель_Пессимист!C132 -> 0.04 | C22: =Модель_База!C132 -> 0.05 | D22: =Модель_Оптимист!C132 -> 0.08
A24: Проверки по условиям кейса
A25: Бюджет: пиковая потребность ≤ лимита (10 млрд ₽) | B25: =IF(B10<=Допущения!$C$6,"ОК","Превышен лимит") -> ОК | C25: =IF(C10<=Допущения!$C$6,"ОК","Превышен лимит") -> ОК | D25: =IF(D10<=Допущения!$C$6,"ОК","Превышен лимит") -> ОК
A26: Срок: окупаемость ≤ 12 кварталов | B26: =IF(ISNUMBER(B7),IF(B7<=Допущения!$C$7,"ОК","Дольше 3 лет"),"Не окупается за 3 года") -> Не окупается за 3 года | C26: =IF(ISNUMBER(C7),IF(C7<=Допущения!$C$7,"ОК","Дольше 3 лет"),"Не окупается за 3 года") -> Не окупается за 3 года | D26: =IF(ISNUMBER(D7),IF(D7<=Допущения!$C$7,"ОК","Дольше 3 лет"),"Не окупается за 3 года") -> ОК
A27: Срок: дисконтированная окупаемость ≤ 12 кварталов | B27: =IF(ISNUMBER(B8),IF(B8<=Допущения!$C$7,"ОК","Дольше 3 лет"),"Не окупается за 3 года") -> Не окупается за 3 года | C27: =IF(ISNUMBER(C8),IF(C8<=Допущения!$C$7,"ОК","Дольше 3 лет"),"Не окупается за 3 года") -> Не окупается за 3 года | D27: =IF(ISNUMBER(D8),IF(D8<=Допущения!$C$7,"ОК","Дольше 3 лет"),"Не окупается за 3 года") -> ОК
A28: Контрольное условие: чистый эффект на сделки ≥ 0 (контакты не падают) | B28: =IF(B19>=0,"ОК","Сделки падают") -> ОК | C28: =IF(C19>=0,"ОК","Сделки падают") -> ОК | D28: =IF(D19>=0,"ОК","Сделки падают") -> ОК
A30: 2. По годам — Пессимист, млн ₽ | B30: 2027 | C30: 2028 | D30: 2029 | E30: Итого
A31: Эффект 1: конверсия в сделку | B31: =Модель_Пессимист!Q84 -> 0.9926345 | C31: =Модель_Пессимист!R84 -> 13.232303 | D31: =Модель_Пессимист!S84 -> 37.967258 | E31: =Модель_Пессимист!T84 -> 52.192196
A32: Эффект 2: продвижение новых объявлений | B32: =Модель_Пессимист!Q85 -> 0 | C32: =Модель_Пессимист!R85 -> 0.022598754 | D32: =Модель_Пессимист!S85 -> 0.095471631 | E32: =Модель_Пессимист!T85 -> 0.11807038
A33: Эффект 2: сделки по новым объявлениям | B33: =Модель_Пессимист!Q86 -> 0 | C33: =Модель_Пессимист!R86 -> 0.058756759 | D33: =Модель_Пессимист!S86 -> 0.25815529 | E33: =Модель_Пессимист!T86 -> 0.31691205
A34: Эффект 3: визиты (реклама, рекомендации) | B34: =Модель_Пессимист!Q89 -> 0.115668 | C34: =Модель_Пессимист!R89 -> 1.439424 | D34: =Модель_Пессимист!S89 -> 3.8556 | E34: =Модель_Пессимист!T89 -> 5.410692
A35: Эффект 4: удержание | B35: =Модель_Пессимист!Q90 -> 0 | C35: =Модель_Пессимист!R90 -> 0 | D35: =Модель_Пессимист!S90 -> 0 | E35: =Модель_Пессимист!T90 -> 0
A36: Дополнительная выручка всего | B36: =Модель_Пессимист!Q91 -> 1.1083025 | C36: =Модель_Пессимист!R91 -> 14.753083 | D36: =Модель_Пессимист!S91 -> 42.176485 | E36: =Модель_Пессимист!T91 -> 58.03787
A37: Маржинальный доход | B37: =Модель_Пессимист!Q92 -> 0.94205712 | C37: =Модель_Пессимист!R92 -> 12.54012 | D37: =Модель_Пессимист!S92 -> 35.850012 | E37: =Модель_Пессимист!T92 -> 49.33219
A38: Затраты: команда разработки | B38: =Модель_Пессимист!Q96 -> 81 | C38: =Модель_Пессимист!R96 -> 110.808 | D38: =Модель_Пессимист!S96 -> 125.9712 | E38: =Модель_Пессимист!T96 -> 317.7792
A39: Затраты: модерация (ИИ + ручная) | B39: =Модель_Пессимист!Q98+Модель_Пессимист!Q99 -> 0.19807673 | C39: =Модель_Пессимист!R98+Модель_Пессимист!R99 -> 2.5389034 | D39: =Модель_Пессимист!S98+Модель_Пессимист!S99 -> 7.0046533 | E39: =Модель_Пессимист!T98+Модель_Пессимист!T99 -> 9.7416334
A40: Затраты: ИИ и инфраструктура | B40: =Модель_Пессимист!Q100 -> 7.5600233 | C40: =Модель_Пессимист!R100 -> 10.769365 | D40: =Модель_Пессимист!S100 -> 12.122622 | E40: =Модель_Пессимист!T100 -> 30.45201
A41: Затраты: мотивация авторов | B41: =Модель_Пессимист!Q101 -> 0.6002325 | C41: =Модель_Пессимист!R101 -> 7.6936468 | D41: =Модель_Пессимист!S101 -> 21.226222 | E41: =Модель_Пессимист!T101 -> 29.520101
A42: Затраты: маркетинг | B42: =Модель_Пессимист!Q102 -> 60 | C42: =Модель_Пессимист!R102 -> 16 | D42: =Модель_Пессимист!S102 -> 16 | E42: =Модель_Пессимист!T102 -> 92
A43: Затраты: резерв | B43: =Модель_Пессимист!Q104 -> 14.935833 | C43: =Модель_Пессимист!R104 -> 14.780991 | D43: =Модель_Пессимист!S104 -> 18.23247 | E43: =Модель_Пессимист!T104 -> 47.949294
...

Sheet Допущения
A1: Допущения модели
A2: Синий — ввод; жёлтая заливка — ключевое допущение (проверить на пилоте). Цифры вне открытых данных — допущения команды.Все числа вне открытых данных — допущения команды (черновые, подбираем вместе).
A4: Параметр | B4: Ед. | C4: Пессимист | D4: База | E4: Оптимист | F4: Статус | G4: Источник / комментарий
A5: 1. Рамки кейса и финансовые параметры
A6: Лимит инвестиций (потолок, не цель) | B6: млн ₽ | C6: 10000 | D6: 10000 | E6: 10000 | F6: Факт кейса | G6: Кейс: до 10 млрд ₽ на 3 года.
A7: Максимальный срок окупаемости | B7: кварталов | C7: 12 | D7: 12 | E7: 12 | F7: Факт кейса | G7: Кейс: окупаемость до 3 лет.
A8: Ставка дисконтирования (годовая) | B8: % год | C8: 0.15 | D8: 0.15 | E8: 0.15 | F8: Допущение команды | G8: Ключевая ставка ЦБ 14% + 1 п.п.
A9: Маржа инкрементального дохода (после переменных издержек сделок) | B9: % | C9: 0.85 | D9: 0.85 | E9: 0.85 | F9: Допущение команды | G9: Доля выручки после переменных издержек. Без налогов.
A10: 2. Рынок и стартовая база
A11: Товарные сделки на платформе в год (база 2026) | B11: млн шт. | C11: 200 | D11: 200 | E11: 200 | F11: Открытые данные | G11: Forbes, А. Гевлич (2023): более 200 млн.
A12: Рост числа товарных сделок в год | B12: % год | C12: 0.03 | D12: 0.07 | E12: 0.1 | F12: Допущение команды | G12: Заказы с Доставкой в 2025: +30% (Retail.ru).
A13: Доля товарных сделок с Авито Доставкой (2026) | B13: % | C13: 0.37 | D13: 0.4 | E13: 0.43 | F13: Открытые данные | G13: МойСклад/Авито: 27% (I пол. 2024) → 37% (I пол. 2025).
A14: Рост доли Доставки в год | B14: п.п./год | C14: 0 | D14: 0.03 | E14: 0.04 | F14: Допущение команды | G14: В 2025 к 2024: +10 п.п.; берём 0–4.
A15: Месячная аудитория Авито | B15: млн чел. | C15: 51 | D15: 51 | E15: 51 | F15: Факт кейса | G15: Кейс: более 51 млн (сентябрь 2026). Без роста.
A16: 3. Охват механики
A17: Доля сделок Доставки в охваченных категориях — Год 1 | B17: % | C17: 0.21 | D17: 0.31 | E17: 0.39 | F17: Открытые данные | G17: Доли категорий в заказах с Доставкой (2025): хобби 15%, запчасти 10%, красота 8%, спорт 6%. Пессимист: хобби+спорт; база: +запчасти; оптимист: +красота.
A18: то же — Год 2 | B18: % | C18: 0.28 | D18: 0.55 | E18: 0.62 | F18: Допущение команды | G18: Расширение на соседние категории.
A19: то же — Год 3 | B19: % | C19: 0.35 | D19: 0.7 | E19: 0.78 | F19: Допущение команды | G19: Пессимист: без расширения.
A20: Доля сделок, идущих через карточки с блоком опыта (на зрелости) | B20: % | C20: 0.35 | D20: 0.45 | E20: 0.55 | F20: Допущение команды | G20: Блок виден только там, где набрано достаточно отзывов.
A21: 4. Воронка отзывов
A22: Доля подтверждённых покупателей, оставивших отзыв о модели (на зрелости) | B22: % | C22: 0.05 | D22: 0.08 | E22: 0.1 | F22: Допущение команды | G22: Авито (2024): после покупки товаров отзыв оставляют >23%, услуг >17%. Отзыв о модели сложнее.
A23: Доля авторов, обновивших отзыв позже / с долгим сроком использования | B23: % | C23: 0.15 | D23: 0.25 | E23: 0.35 | F23: Допущение команды | G23: Они же — аудитория пуша «оцените и продайте».
A24: Срок использования до пуша «оцените и продайте» | B24: кварталов | C24: 2 | D24: 2 | E24: 2 | F24: Допущение команды | G24: 2 кв. ≈ 6 мес.
A25: Доля обновивших отзыв, выставивших вещь через «Можно продать» | B25: % | C25: 0.05 | D25: 0.08 | E25: 0.12 | F25: Допущение команды | G25: Проверить на пилоте.
A26: Доля выставивших вещь, купивших продвижение | B26: % | C26: 0.12 | D26: 0.18 | E26: 0.25 | F26: Допущение команды
A27: Средний платёж за продвижение | B27: ₽ | C27: 150 | D27: 200 | E27: 250 | F27: Допущение команды
A28: Доля выставленных вещей, проданных через Доставку | B28: % | C28: 0.2 | D28: 0.3 | E28: 0.4 | F28: Допущение команды | G28: Доля новых объявлений, дошедших до сделки через Доставку.
A29: 5. Конверсия и доход со сделки
A30: Прирост конверсии в сделку в карточках с блоком (относительный) | B30: % | C30: 0.04 | D30: 0.05 | E30: 0.08 | F30: Оценка по бенчмарку | G30: Вилка 3–7% из данных Авито о видео, см. лист «Обоснование_uplift». Проверить A/B-тестом.
A31: Доля прироста, действительно инкрементальная | B31: % | C31: 0.65 | D31: 0.75 | E31: 0.85 | F31: Допущение команды | G31: За вычетом перетока сделок из других объявлений.
A32: Негативный эффект: потеря сделок в охваченных карточках (слабые модели, меньше контактов) | B32: % | C32: 0.005 | D32: 0.003 | E32: 0.0015 | F32: Допущение команды | G32: Риск: слабые модели теряют спрос, покупатели реже пишут продавцу. Контроль — контакты.
A33: Средний чек сделки с Доставкой | B33: ₽ | C33: 2000 | D33: 2000 | E33: 2000 | F33: Со слов команды (созвон) | G33: Созвон: около 2 000 ₽.
A34: Доход Авито с оборота сделки через Доставку | B34: % | C34: 0.1125 | D34: 0.125 | E34: 0.125 | F34: Со слов команды (созвон) | G34: Созвон: комиссия около 250 ₽ (12,5% чека). Пессимист — 225 ₽.
A35: Индексация среднего чека и комиссии в год (сложный процент) | B35: % год | C35: 0.04 | D35: 0.06 | E35: 0.07 | F35: Допущение команды | G35: Рост чека и комиссии со 2-го года: (1+i)^(год−1).
A36: 6. Визиты (эффект 3)
A37: Доля аудитории охваченных категорий, пользующаяся блоком в месяц (на зрелости) | B37: % | C37: 0.12 | D37: 0.15 | E37: 0.2 | F37: Допущение команды | G37: Читатели, авторы, участники обсуждений.
A38: Дополнительных визитов на участника в месяц | B38: визитов | C38: 0.5 | D38: 0.8 | E38: 1.1 | F38: Допущение команды | G38: Только новые визиты.
A39: Просмотров за дополнительный визит | B39: шт. | C39: 8 | D39: 10 | E39: 12 | F39: Допущение команды
A40: Доход от рекламы и рекомендаций на один просмотр | B40: ₽ | C40: 0.05 | D40: 0.08 | E40: 0.11 | F40: Допущение команды | G40: 40–120 ₽ за 1000 просмотров.
A41: 7. Удержание (эффект 4 — верхний сценарий)
...

Sheet Обоснование_uplift
A1: Обоснование прироста конверсии в сделку
A2: Прямых данных по механике нет. Вилка выводится из внутреннего ориентира Авито. Точное значение даст A/B-тест.
A4: Показатель | B4: Низ | C4: Середина | D4: Верх | E4: Источник
A5: Рост взаимодействий от видео в объявлениях | B5: 0.06 | C5: 0.08 | D5: 0.1 | E5: Авито (кейс): +6–10%.
A6: Доля прироста взаимодействий, доходящая до сделки | B6: 0.5 | C6: 0.6 | D6: 0.7 | E6: Допущение. Проверяется на пилоте.
A7: Прирост конверсии в сделку (1 × 2) | B7: =B5*B6 -> 0.03 | C7: =C5*C6 -> 0.048 | D7: =D5*D6 -> 0.07
A8: Надбавка: отзывы владельцев сильнее видео | B8: 0 | C8: 0 | D8: 0.01 | E8: Суждение: только для оптимиста, +1 п.п.
A9: Вилка с надбавкой | B9: =B7+B8 -> 0.03 | C9: =C7+C8 -> 0.048 | D9: =D7+D8 -> 0.08
A11: Принято в модели | B11: Пессимист | C11: База | D11: Оптимист
A12: Прирост конверсии (лист «Допущения») | B12: =Допущения!C30 -> 0.04 | C12: =Допущения!D30 -> 0.05 | D12: =Допущения!E30 -> 0.08
A13: Мин. прирост: простая окупаемость за 12 кв. | B13: =Модель_Пессимист!C135 -> 0.3881844 | C13: =Модель_База!C135 -> 0.060507692 | D13: =Модель_Оптимист!C135 -> 0.028531037
A14: Мин. прирост: дисконтированная окупаемость за 12 кв. | B14: =Модель_Пессимист!C134 -> 0.42694901 | C14: =Модель_База!C134 -> 0.064461692 | D14: =Модель_Оптимист!C134 -> 0.031061689
A15: Запас: принято − мин. (простая), п.п. | B15: =IF(ISNUMBER(B13),B12-B13,"н/д") -> -0.3481844 | C15: =IF(ISNUMBER(C13),C12-C13,"н/д") -> -0.010507692 | D15: =IF(ISNUMBER(D13),D12-D13,"н/д") -> 0.051468963
A17: Что не использовано как оценка
A18: Spiegel Research Center (2017): +190–380% при 5 отзывах против 0. Наблюдательные данные, выборка не раскрыта, эффект убывает.
A19: PowerReviews/1WorldSync: 74% читают Q&A, 24% подозрительнее без него. Опрос, числа по конверсии нет.
A20: Вывод: направление эффекта подтверждено, величина — нет. Порог окупаемости базы лежит внутри вилки, поэтому нужен A/B-тест (ноутбук ab_test.ipynb).

Sheet Модель_Пессимист
A1: Финмодель - сценарий: Пессимист
A2: Номер сценария на листе (1 = Пессимист, 2 = База, 3 = Оптимист) | C2: 1
A3: Сценарий | C3: =INDEX(Допущения!$C$4:$E$4,$C$2) -> Пессимист
A4: Деньги — млн ₽, объёмы — тыс. шт. за квартал. Допущения — с листа «Допущения».
A5: Квартал № | D5: 1 | E5: =D5+1 -> 2 | F5: =E5+1 -> 3 | G5: =F5+1 -> 4 | H5: =G5+1 -> 5 | I5: =H5+1 -> 6 | J5: =I5+1 -> 7 | K5: =J5+1 -> 8 | L5: =K5+1 -> 9 | ... O5: =N5+1 -> 12
A6: Год проекта | D6: =ROUNDUP(D5/4,0) -> 1 | E6: =ROUNDUP(E5/4,0) -> 1 | F6: =ROUNDUP(F5/4,0) -> 1 | G6: =ROUNDUP(G5/4,0) -> 1 | H6: =ROUNDUP(H5/4,0) -> 2 | I6: =ROUNDUP(I5/4,0) -> 2 | J6: =ROUNDUP(J5/4,0) -> 2 | K6: =ROUNDUP(K5/4,0) -> 2 | ... O6: =ROUNDUP(O5/4,0) -> 3 | Q6: 1 | R6: 2 | S6: 3
A7: Период | C7: Параметр | D7: ="Q"&(MOD(D5-1,4)+1)&" "&(2026+D6) -> Q1 2027 | E7: ="Q"&(MOD(E5-1,4)+1)&" "&(2026+E6) -> Q2 2027 | F7: ="Q"&(MOD(F5-1,4)+1)&" "&(2026+F6) -> Q3 2027 | G7: ="Q"&(MOD(G5-1,4)+1)&" "&(2026+G6) -> Q4 2027 | H7: ="Q"&(MOD(H5-1,4)+1)&" "&(2026+H6) -> Q1 2028 | I7: ="Q"&(MOD(I5-1,4)+1)&" "&(2026+I6) -> Q2 2028 | J7: ="Q"&(MOD(J5-1,4)+1)&" "&(2026+J6) -> Q3 2028 | K7: ="Q"&(MOD(K5-1,4)+1)&" "&(2026+K6) -> Q4 2028 | ... O7: ="Q"&(MOD(O5-1,4)+1)&" "&(2026+O6) -> Q4 2029 | Q7: 2027 | R7: 2028 | S7: 2029 | T7: Итого
A9: Параметры сценария (из листа «Допущения»)
A10: Лимит инвестиций (потолок, не цель) | B10: млн ₽ | C10: =INDEX(Допущения!$C$6:$E$6,$C$2) -> 10000
A11: Максимальный срок окупаемости | B11: кварталов | C11: =INDEX(Допущения!$C$7:$E$7,$C$2) -> 12
A12: Ставка дисконтирования (годовая) | B12: % год | C12: =INDEX(Допущения!$C$8:$E$8,$C$2) -> 0.15
A13: Маржа инкрементального дохода (после переменных издержек сделок) | B13: % | C13: =INDEX(Допущения!$C$9:$E$9,$C$2) -> 0.85
A14: Товарные сделки на платформе в год (база 2026) | B14: млн шт. | C14: =INDEX(Допущения!$C$11:$E$11,$C$2) -> 200
A15: Рост числа товарных сделок в год | B15: % год | C15: =INDEX(Допущения!$C$12:$E$12,$C$2) -> 0.03
A16: Доля товарных сделок с Авито Доставкой (2026) | B16: % | C16: =INDEX(Допущения!$C$13:$E$13,$C$2) -> 0.37
A17: Рост доли Доставки в год | B17: п.п./год | C17: =INDEX(Допущения!$C$14:$E$14,$C$2) -> 0
A18: Месячная аудитория Авито | B18: млн чел. | C18: =INDEX(Допущения!$C$15:$E$15,$C$2) -> 51
A19: Доля сделок Доставки в охваченных категориях — Год 1 | B19: % | C19: =INDEX(Допущения!$C$17:$E$17,$C$2) -> 0.21
A20: то же — Год 2 | B20: % | C20: =INDEX(Допущения!$C$18:$E$18,$C$2) -> 0.28
A21: то же — Год 3 | B21: % | C21: =INDEX(Допущения!$C$19:$E$19,$C$2) -> 0.35
A22: Доля сделок, идущих через карточки с блоком опыта (на зрелости) | B22: % | C22: =INDEX(Допущения!$C$20:$E$20,$C$2) -> 0.35
A23: Доля подтверждённых покупателей, оставивших отзыв о модели (на зрелости) | B23: % | C23: =INDEX(Допущения!$C$22:$E$22,$C$2) -> 0.05
A24: Доля авторов, обновивших отзыв позже / с долгим сроком использования | B24: % | C24: =INDEX(Допущения!$C$23:$E$23,$C$2) -> 0.15
A25: Срок использования до пуша «оцените и продайте» | B25: кварталов | C25: =INDEX(Допущения!$C$24:$E$24,$C$2) -> 2
A26: Доля обновивших отзыв, выставивших вещь через «Можно продать» | B26: % | C26: =INDEX(Допущения!$C$25:$E$25,$C$2) -> 0.05
A27: Доля выставивших вещь, купивших продвижение | B27: % | C27: =INDEX(Допущения!$C$26:$E$26,$C$2) -> 0.12
A28: Средний платёж за продвижение | B28: ₽ | C28: =INDEX(Допущения!$C$27:$E$27,$C$2) -> 150
A29: Доля выставленных вещей, проданных через Доставку | B29: % | C29: =INDEX(Допущения!$C$28:$E$28,$C$2) -> 0.2
A30: Прирост конверсии в сделку в карточках с блоком (относительный) | B30: % | C30: =INDEX(Допущения!$C$30:$E$30,$C$2) -> 0.04
A31: Негативный эффект: потеря сделок в охваченных карточках (слабые модели, меньше контактов) | B31: % | C31: =INDEX(Допущения!$C$32:$E$32,$C$2) -> 0.005
A32: Доля прироста, действительно инкрементальная | B32: % | C32: =INDEX(Допущения!$C$31:$E$31,$C$2) -> 0.65
A33: Средний чек сделки с Доставкой | B33: ₽ | C33: =INDEX(Допущения!$C$33:$E$33,$C$2) -> 2000
A34: Доход Авито с оборота сделки через Доставку | B34: % | C34: =INDEX(Допущения!$C$34:$E$34,$C$2) -> 0.1125
A35: Индексация среднего чека и комиссии в год (сложный процент) | B35: % год | C35: =INDEX(Допущения!$C$35:$E$35,$C$2) -> 0.04
A36: Доход Авито с одной сделки через Доставку | B36: ₽ | C36: =$C$33*$C$34 -> 225
A37: Доля аудитории охваченных категорий, пользующаяся блоком в месяц (на зрелости) | B37: % | C37: =INDEX(Допущения!$C$37:$E$37,$C$2) -> 0.12
A38: Дополнительных визитов на участника в месяц | B38: визитов | C38: =INDEX(Допущения!$C$38:$E$38,$C$2) -> 0.5
A39: Просмотров за дополнительный визит | B39: шт. | C39: =INDEX(Допущения!$C$39:$E$39,$C$2) -> 8
A40: Доход от рекламы и рекомендаций на один просмотр | B40: ₽ | C40: =INDEX(Допущения!$C$40:$E$40,$C$2) -> 0.05
A41: Доп. сделок в год на участника за счёт удержания (по всей платформе) | B41: сделок/год | C41: =INDEX(Допущения!$C$42:$E$42,$C$2) -> 0
...

Sheet Модель_База
A1: Финмодель - сценарий: База
A2: Номер сценария на листе (1 = Пессимист, 2 = База, 3 = Оптимист) | C2: 2
A3: Сценарий | C3: =INDEX(Допущения!$C$4:$E$4,$C$2) -> База
A4: Деньги — млн ₽, объёмы — тыс. шт. за квартал. Допущения — с листа «Допущения».
A5: Квартал № | D5: 1 | E5: =D5+1 -> 2 | F5: =E5+1 -> 3 | G5: =F5+1 -> 4 | H5: =G5+1 -> 5 | I5: =H5+1 -> 6 | J5: =I5+1 -> 7 | K5: =J5+1 -> 8 | L5: =K5+1 -> 9 | ... O5: =N5+1 -> 12
A6: Год проекта | D6: =ROUNDUP(D5/4,0) -> 1 | E6: =ROUNDUP(E5/4,0) -> 1 | F6: =ROUNDUP(F5/4,0) -> 1 | G6: =ROUNDUP(G5/4,0) -> 1 | H6: =ROUNDUP(H5/4,0) -> 2 | I6: =ROUNDUP(I5/4,0) -> 2 | J6: =ROUNDUP(J5/4,0) -> 2 | K6: =ROUNDUP(K5/4,0) -> 2 | ... O6: =ROUNDUP(O5/4,0) -> 3 | Q6: 1 | R6: 2 | S6: 3
A7: Период | C7: Параметр | D7: ="Q"&(MOD(D5-1,4)+1)&" "&(2026+D6) -> Q1 2027 | E7: ="Q"&(MOD(E5-1,4)+1)&" "&(2026+E6) -> Q2 2027 | F7: ="Q"&(MOD(F5-1,4)+1)&" "&(2026+F6) -> Q3 2027 | G7: ="Q"&(MOD(G5-1,4)+1)&" "&(2026+G6) -> Q4 2027 | H7: ="Q"&(MOD(H5-1,4)+1)&" "&(2026+H6) -> Q1 2028 | I7: ="Q"&(MOD(I5-1,4)+1)&" "&(2026+I6) -> Q2 2028 | J7: ="Q"&(MOD(J5-1,4)+1)&" "&(2026+J6) -> Q3 2028 | K7: ="Q"&(MOD(K5-1,4)+1)&" "&(2026+K6) -> Q4 2028 | ... O7: ="Q"&(MOD(O5-1,4)+1)&" "&(2026+O6) -> Q4 2029 | Q7: 2027 | R7: 2028 | S7: 2029 | T7: Итого
A9: Параметры сценария (из листа «Допущения»)
A10: Лимит инвестиций (потолок, не цель) | B10: млн ₽ | C10: =INDEX(Допущения!$C$6:$E$6,$C$2) -> 10000
A11: Максимальный срок окупаемости | B11: кварталов | C11: =INDEX(Допущения!$C$7:$E$7,$C$2) -> 12
A12: Ставка дисконтирования (годовая) | B12: % год | C12: =INDEX(Допущения!$C$8:$E$8,$C$2) -> 0.15
A13: Маржа инкрементального дохода (после переменных издержек сделок) | B13: % | C13: =INDEX(Допущения!$C$9:$E$9,$C$2) -> 0.85
A14: Товарные сделки на платформе в год (база 2026) | B14: млн шт. | C14: =INDEX(Допущения!$C$11:$E$11,$C$2) -> 200
A15: Рост числа товарных сделок в год | B15: % год | C15: =INDEX(Допущения!$C$12:$E$12,$C$2) -> 0.07
A16: Доля товарных сделок с Авито Доставкой (2026) | B16: % | C16: =INDEX(Допущения!$C$13:$E$13,$C$2) -> 0.4
A17: Рост доли Доставки в год | B17: п.п./год | C17: =INDEX(Допущения!$C$14:$E$14,$C$2) -> 0.03
A18: Месячная аудитория Авито | B18: млн чел. | C18: =INDEX(Допущения!$C$15:$E$15,$C$2) -> 51
A19: Доля сделок Доставки в охваченных категориях — Год 1 | B19: % | C19: =INDEX(Допущения!$C$17:$E$17,$C$2) -> 0.31
A20: то же — Год 2 | B20: % | C20: =INDEX(Допущения!$C$18:$E$18,$C$2) -> 0.55
A21: то же — Год 3 | B21: % | C21: =INDEX(Допущения!$C$19:$E$19,$C$2) -> 0.7
A22: Доля сделок, идущих через карточки с блоком опыта (на зрелости) | B22: % | C22: =INDEX(Допущения!$C$20:$E$20,$C$2) -> 0.45
A23: Доля подтверждённых покупателей, оставивших отзыв о модели (на зрелости) | B23: % | C23: =INDEX(Допущения!$C$22:$E$22,$C$2) -> 0.08
A24: Доля авторов, обновивших отзыв позже / с долгим сроком использования | B24: % | C24: =INDEX(Допущения!$C$23:$E$23,$C$2) -> 0.25
A25: Срок использования до пуша «оцените и продайте» | B25: кварталов | C25: =INDEX(Допущения!$C$24:$E$24,$C$2) -> 2
A26: Доля обновивших отзыв, выставивших вещь через «Можно продать» | B26: % | C26: =INDEX(Допущения!$C$25:$E$25,$C$2) -> 0.08
A27: Доля выставивших вещь, купивших продвижение | B27: % | C27: =INDEX(Допущения!$C$26:$E$26,$C$2) -> 0.18
A28: Средний платёж за продвижение | B28: ₽ | C28: =INDEX(Допущения!$C$27:$E$27,$C$2) -> 200
A29: Доля выставленных вещей, проданных через Доставку | B29: % | C29: =INDEX(Допущения!$C$28:$E$28,$C$2) -> 0.3
A30: Прирост конверсии в сделку в карточках с блоком (относительный) | B30: % | C30: =INDEX(Допущения!$C$30:$E$30,$C$2) -> 0.05
A31: Негативный эффект: потеря сделок в охваченных карточках (слабые модели, меньше контактов) | B31: % | C31: =INDEX(Допущения!$C$32:$E$32,$C$2) -> 0.003
A32: Доля прироста, действительно инкрементальная | B32: % | C32: =INDEX(Допущения!$C$31:$E$31,$C$2) -> 0.75
A33: Средний чек сделки с Доставкой | B33: ₽ | C33: =INDEX(Допущения!$C$33:$E$33,$C$2) -> 2000
A34: Доход Авито с оборота сделки через Доставку | B34: % | C34: =INDEX(Допущения!$C$34:$E$34,$C$2) -> 0.125
A35: Индексация среднего чека и комиссии в год (сложный процент) | B35: % год | C35: =INDEX(Допущения!$C$35:$E$35,$C$2) -> 0.06
A36: Доход Авито с одной сделки через Доставку | B36: ₽ | C36: =$C$33*$C$34 -> 250
A37: Доля аудитории охваченных категорий, пользующаяся блоком в месяц (на зрелости) | B37: % | C37: =INDEX(Допущения!$C$37:$E$37,$C$2) -> 0.15
A38: Дополнительных визитов на участника в месяц | B38: визитов | C38: =INDEX(Допущения!$C$38:$E$38,$C$2) -> 0.8
A39: Просмотров за дополнительный визит | B39: шт. | C39: =INDEX(Допущения!$C$39:$E$39,$C$2) -> 10
A40: Доход от рекламы и рекомендаций на один просмотр | B40: ₽ | C40: =INDEX(Допущения!$C$40:$E$40,$C$2) -> 0.08
A41: Доп. сделок в год на участника за счёт удержания (по всей платформе) | B41: сделок/год | C41: =INDEX(Допущения!$C$42:$E$42,$C$2) -> 0
...

Sheet Модель_Оптимист
A1: Финмодель - сценарий: Оптимист
A2: Номер сценария на листе (1 = Пессимист, 2 = База, 3 = Оптимист) | C2: 3
A3: Сценарий | C3: =INDEX(Допущения!$C$4:$E$4,$C$2) -> Оптимист
A4: Деньги — млн ₽, объёмы — тыс. шт. за квартал. Допущения — с листа «Допущения».
A5: Квартал № | D5: 1 | E5: =D5+1 -> 2 | F5: =E5+1 -> 3 | G5: =F5+1 -> 4 | H5: =G5+1 -> 5 | I5: =H5+1 -> 6 | J5: =I5+1 -> 7 | K5: =J5+1 -> 8 | L5: =K5+1 -> 9 | ... O5: =N5+1 -> 12
A6: Год проекта | D6: =ROUNDUP(D5/4,0) -> 1 | E6: =ROUNDUP(E5/4,0) -> 1 | F6: =ROUNDUP(F5/4,0) -> 1 | G6: =ROUNDUP(G5/4,0) -> 1 | H6: =ROUNDUP(H5/4,0) -> 2 | I6: =ROUNDUP(I5/4,0) -> 2 | J6: =ROUNDUP(J5/4,0) -> 2 | K6: =ROUNDUP(K5/4,0) -> 2 | ... O6: =ROUNDUP(O5/4,0) -> 3 | Q6: 1 | R6: 2 | S6: 3
A7: Период | C7: Параметр | D7: ="Q"&(MOD(D5-1,4)+1)&" "&(2026+D6) -> Q1 2027 | E7: ="Q"&(MOD(E5-1,4)+1)&" "&(2026+E6) -> Q2 2027 | F7: ="Q"&(MOD(F5-1,4)+1)&" "&(2026+F6) -> Q3 2027 | G7: ="Q"&(MOD(G5-1,4)+1)&" "&(2026+G6) -> Q4 2027 | H7: ="Q"&(MOD(H5-1,4)+1)&" "&(2026+H6) -> Q1 2028 | I7: ="Q"&(MOD(I5-1,4)+1)&" "&(2026+I6) -> Q2 2028 | J7: ="Q"&(MOD(J5-1,4)+1)&" "&(2026+J6) -> Q3 2028 | K7: ="Q"&(MOD(K5-1,4)+1)&" "&(2026+K6) -> Q4 2028 | ... O7: ="Q"&(MOD(O5-1,4)+1)&" "&(2026+O6) -> Q4 2029 | Q7: 2027 | R7: 2028 | S7: 2029 | T7: Итого
A9: Параметры сценария (из листа «Допущения»)
A10: Лимит инвестиций (потолок, не цель) | B10: млн ₽ | C10: =INDEX(Допущения!$C$6:$E$6,$C$2) -> 10000
A11: Максимальный срок окупаемости | B11: кварталов | C11: =INDEX(Допущения!$C$7:$E$7,$C$2) -> 12
A12: Ставка дисконтирования (годовая) | B12: % год | C12: =INDEX(Допущения!$C$8:$E$8,$C$2) -> 0.15
A13: Маржа инкрементального дохода (после переменных издержек сделок) | B13: % | C13: =INDEX(Допущения!$C$9:$E$9,$C$2) -> 0.85
A14: Товарные сделки на платформе в год (база 2026) | B14: млн шт. | C14: =INDEX(Допущения!$C$11:$E$11,$C$2) -> 200
A15: Рост числа товарных сделок в год | B15: % год | C15: =INDEX(Допущения!$C$12:$E$12,$C$2) -> 0.1
A16: Доля товарных сделок с Авито Доставкой (2026) | B16: % | C16: =INDEX(Допущения!$C$13:$E$13,$C$2) -> 0.43
A17: Рост доли Доставки в год | B17: п.п./год | C17: =INDEX(Допущения!$C$14:$E$14,$C$2) -> 0.04
A18: Месячная аудитория Авито | B18: млн чел. | C18: =INDEX(Допущения!$C$15:$E$15,$C$2) -> 51
A19: Доля сделок Доставки в охваченных категориях — Год 1 | B19: % | C19: =INDEX(Допущения!$C$17:$E$17,$C$2) -> 0.39
A20: то же — Год 2 | B20: % | C20: =INDEX(Допущения!$C$18:$E$18,$C$2) -> 0.62
A21: то же — Год 3 | B21: % | C21: =INDEX(Допущения!$C$19:$E$19,$C$2) -> 0.78
A22: Доля сделок, идущих через карточки с блоком опыта (на зрелости) | B22: % | C22: =INDEX(Допущения!$C$20:$E$20,$C$2) -> 0.55
A23: Доля подтверждённых покупателей, оставивших отзыв о модели (на зрелости) | B23: % | C23: =INDEX(Допущения!$C$22:$E$22,$C$2) -> 0.1
A24: Доля авторов, обновивших отзыв позже / с долгим сроком использования | B24: % | C24: =INDEX(Допущения!$C$23:$E$23,$C$2) -> 0.35
A25: Срок использования до пуша «оцените и продайте» | B25: кварталов | C25: =INDEX(Допущения!$C$24:$E$24,$C$2) -> 2
A26: Доля обновивших отзыв, выставивших вещь через «Можно продать» | B26: % | C26: =INDEX(Допущения!$C$25:$E$25,$C$2) -> 0.12
A27: Доля выставивших вещь, купивших продвижение | B27: % | C27: =INDEX(Допущения!$C$26:$E$26,$C$2) -> 0.25
A28: Средний платёж за продвижение | B28: ₽ | C28: =INDEX(Допущения!$C$27:$E$27,$C$2) -> 250
A29: Доля выставленных вещей, проданных через Доставку | B29: % | C29: =INDEX(Допущения!$C$28:$E$28,$C$2) -> 0.4
A30: Прирост конверсии в сделку в карточках с блоком (относительный) | B30: % | C30: =INDEX(Допущения!$C$30:$E$30,$C$2) -> 0.08
A31: Негативный эффект: потеря сделок в охваченных карточках (слабые модели, меньше контактов) | B31: % | C31: =INDEX(Допущения!$C$32:$E$32,$C$2) -> 0.0015
A32: Доля прироста, действительно инкрементальная | B32: % | C32: =INDEX(Допущения!$C$31:$E$31,$C$2) -> 0.85
A33: Средний чек сделки с Доставкой | B33: ₽ | C33: =INDEX(Допущения!$C$33:$E$33,$C$2) -> 2000
A34: Доход Авито с оборота сделки через Доставку | B34: % | C34: =INDEX(Допущения!$C$34:$E$34,$C$2) -> 0.125
A35: Индексация среднего чека и комиссии в год (сложный процент) | B35: % год | C35: =INDEX(Допущения!$C$35:$E$35,$C$2) -> 0.07
A36: Доход Авито с одной сделки через Доставку | B36: ₽ | C36: =$C$33*$C$34 -> 250
A37: Доля аудитории охваченных категорий, пользующаяся блоком в месяц (на зрелости) | B37: % | C37: =INDEX(Допущения!$C$37:$E$37,$C$2) -> 0.2
A38: Дополнительных визитов на участника в месяц | B38: визитов | C38: =INDEX(Допущения!$C$38:$E$38,$C$2) -> 1.1
A39: Просмотров за дополнительный визит | B39: шт. | C39: =INDEX(Допущения!$C$39:$E$39,$C$2) -> 12
A40: Доход от рекламы и рекомендаций на один просмотр | B40: ₽ | C40: =INDEX(Допущения!$C$40:$E$40,$C$2) -> 0.11
A41: Доп. сделок в год на участника за счёт удержания (по всей платформе) | B41: сделок/год | C41: =INDEX(Допущения!$C$42:$E$42,$C$2) -> 0.04
...

Sheet Источники
A1: Данные кейса и открытые источники, использованные в модели
A3: Показатель | B3: Значение | C3: Источник / как использовано
A4: Лимит инвестиций | B4: до 10 млрд ₽ за 3 года | C4: Кейс. Потолок, не цель.
A5: Срок окупаемости | B5: до 3 лет | C5: Кейс.
A6: Сделки в Авито Товарах за год | B6: более 200 млн (2023) | C6: Forbes, А. Гевлич.
A7: Доля товарных сделок с Доставкой | B7: 27% (I пол. 2024) → 37% (I пол. 2025) | C7: МойСклад/Авито.
A8: Рост заказов с доставкой | B8: +30% в 2025 к 2024 | C8: Retail.ru/Авито.
A9: Категории в заказах с Доставкой | B9: одежда 30%, хобби 15%, запчасти 10%, красота 8%, спорт 6% (2025) | C9: Retail.ru. База охвата стартовых категорий.
A10: Месячная аудитория | B10: более 51 млн (сентябрь 2026) | C10: Кейс.
A11: Отзывы после покупки | B11: товары >23%, услуги >17% сделок | C11: Авито, ComNews (2024). Ориентир для доли отзывов.
A12: Видео в объявлениях | B12: +6–10% взаимодействий | C12: Авито. Ориентир для прироста конверсии.
A13: Средний чек сделки с Доставкой | B13: около 2 000 ₽ | C13: Созвон команды.
A14: Комиссия Авито со сделки | B14: около 250 ₽ | C14: Созвон команды.
... A18: Вопросы и ответы | B18: 74% читают; 24% подозрительнее без Q&A | C18: PowerReviews/1WorldSync, опрос ~16 тыс.
A20: Логика модели
A21: Воронка: сделки в стартовых категориях → отзыв → обновление отзыва → выставление вещи.
A22: Эффект 1: сделки в карточках с блоком × прирост конверсии × доля инкрементальных − потери, × доход со сделки.
A23: Эффект 2: авторы с долгим сроком × доля выставивших × (продвижение + доход со сделки).
A24: Эффект 3: доп. визиты × просмотры × доход на просмотр. Эффект 4 — только в оптимисте.
A25: Затраты: команда, модерация, ИИ и инфраструктура, мотивация авторов, маркетинг, резерв.
A26: Упрощения: без сезонности и налогов; общий профиль зрелости для всех категорий.
A28: Открытые вопросы к команде
A29: ☐ Какие 3–5 категорий берём на старт.
A30: ☐ Мотивация авторов: бонусы или пожертвование.
A31: ☐ Остаёмся в товарах или расширяем на другие направления.
A32: ☐ Где живут обсуждения: категории, модели или оба уровня.
A33: ☐ Рабочее название для презентации.
